<?xml version="1.0"?>
<robot name="scara_52900">
  <xacro:property name="pi" value="3.1415" />

  <material name="blue">
    <color rgba="0 0 .8 .9"/>
  </material>
  <material name="pvc">
    <color rgba=".8 .8 .8 1"/>
  </material>
  <material name="black">
    <color rgba="0 0 0 1"/>
  </material>
  <material name="aluminum">
    <color rgba=".144 .144 .144 .8"/>
  </material>
  <material name="white">
      <color rgba="1 1 1 1"/>
  </material>
  <material name="red">
      <color rgba="0.8 0 0 1"/>
  </material>
  <material name="green">
      <color rgba="0 1 0 1"/>
  </material>
  <material name="yellow">
      <color rgba="1 1 0 1"/>
  </material>

  <link name="base_link">
    <visual>
      <geometry>
        <box size=".139 .195 .009"/>
      </geometry>
      <material name="pvc"/>
    </visual> 
    <collision>
      <geometry>
        <box size=".139 .195 .009"/>
      </geometry>
    </collision>   
    <inertia ixx="0.4" ixy="0.0" ixz="0.0" iyy="0.4" iyz="0.0" izz="0.2"/>
  </link>

  <link name="scapula">
    <visual>
      <geometry>
        <box size=".155 .134 .320"/>
      </geometry>
      <origin rpy="0 0 0" xyz="0 -.065 .075"/>
      <material name="pvc"/>
    </visual>  
    <collision>
      <geometry>
        <box size=".155 .134 .320"/>
      </geometry>
    </collision>   
    <inertia ixx="0.4" ixy="0.0" ixz="0.0" iyy="0.4" iyz="0.0" izz="0.2"/>  
  </link>

  <joint name="waist" type="revolute">
    <parent link="base_link"/>
    <child link="scapula"/>
    <axis xyz="0 0 1" />
    <origin xyz="0 0 .09"/>
    <limit lower="-3" upper="3" effort="1" velocity="1" />
    <visual>
      <material name="aluminum"/>
    </visual>
  </joint>


  <link name="humerus"> 
    <visual>
      <geometry>
        <box size=".255 .059 .056"/>
      </geometry>
      <origin rpy="0 0 1.57057" xyz="0 .110 0"/>
      <material name="pvc"/>
    </visual>
    <collision>
      <geometry>
        <box size=".255 .059 .056"/>
      </geometry>
    </collision>   
    <inertia ixx="0.4" ixy="0.0" ixz="0.0" iyy="0.4" iyz="0.0" izz="0.2"/> 
  </link>

  <joint name="shoulder" type="prismatic">
    <parent link="scapula"/>
    <child link="humerus"/>
    <axis xyz="0 0 1" />
    <origin xyz="0 0 .04" rpy="0 0 0" />
    <limit lower="0" upper=".155" effort="1" velocity="1"/>
  </joint>

  <link name="forearm">
    <visual>
      <geometry>
        <box size=".205 .06 .072"/>
      </geometry>
      <origin xyz="0 .100 0" rpy="0 0 1.57057" />
      <material name="blue"/>
    </visual>
    <collision>
      <geometry>
        <box size=".205 .06 .072"/>
      </geometry>
    </collision>  
    <inertia ixx="0.4" ixy="0.0" ixz="0.0" iyy="0.4" iyz="0.0" izz="0.2"/> 
  </link>

  <joint name="elbow" type="revolute">
    <parent link="humerus"/>
    <child link="forearm"/>
    <limit lower="-2.44" upper="2.44" effort="1" velocity="1"/>
    <origin xyz="0 .190 -.065" rpy="0 0 0" />
    <axis xyz="0 0 1" />
  </joint>

	<link name="hand">
    <visual>
      <geometry>
        <box size=".03  .129 .009"/>
      </geometry>
      <origin xyz="0 0 0 " rpy="1.57057 0 0"/>
      <material name="red"/>
    </visual>
    <collision>
      <geometry>
        <box size=".03  .129 .009"/>
      </geometry>
    </collision> 
    <inertia ixx="0.4" ixy="0.0" ixz="0.0" iyy="0.4" iyz="0.0" izz="0.2"/>  
	</link>

  <joint name="wrist" type="continuous">
    <parent link="forearm"/>
    <child link="hand"/>
    <origin xyz="0 .1993 -.05" rpy="1.57057 0  0 " />
    <axis xyz="0 1 0" />
  </joint>
</robot>